Workbook

Sheet MAIN
B3: INDONESIAN TRADE FLOW ANALYSIS Exploratory Data Analysis · FY2019–2024
B4: Dataset: 264 records | 12 Commodities | 15 Trading Partners | 6 Years
B5: BPS Indonesia, UN Comtrade, and World Bank trade statistics 2019-2024
B7: ABOUT THIS WORKBOOK
B8: This workbook conducts a structured Exploratory Data Analysis (EDA) on Indonesia's international trade
B9: flows from 2019 to 2024. The dataset covers Indonesia's top export and import commodities across
B10: its primary trading partners, capturing value, volume, price, and logistics mode.
B12: The analysis proceeds from raw data inspection through univariate and bivariate analysis to time-series
B13: trends and trade balance calculations
B15: WORKBOOK STRUCTURE
B16: # | C16: Sheet | E16: What It Contains
B17: 1 | C17: RAW DATA | E17: 264 trade records — all commodities, all partners, all years
B18: 2 | C18: DATA PROFILE | E18: Null counts, unique values, data types, numeric summaries
B19: 3 | C19: UNIVARIATE | E19: Frequency distributions and descriptive stats per variable
B20: 4 | C20: BIVARIATE | E20: Cross-analysis: commodity × partner, export vs import matrices
B21: 5 | C21: TIME SERIES | E21: Year-on-year trends, CAGR, growth rates by commodity and partner
B22: 6 | C22: TRADE BALANCE | E22: Indonesia's trade surplus/deficit by partner and commodity
B23: 7 | C23: KEY FINDINGS | E23: Synthesised analytical insights with supply chain context
B26: KEY DATASET STATISTICS
B27: Total Records | D27: 264 | E27: Export Records | G27: 132 | H27: Import Records | J27: 132
B28: Years Covered | D28: 2019–2024 | E28: Commodities | G28: 12 | H28: Trading Partners | J28: 15
B29: Export Commodities | D29: 6 | E29: Import Commodities | G29: 6 | H29: Regions Covered | J29: 5

Sheet DASHBOARD
A1: 🇮🇩 INDONESIA TRADE FLOW DASHBOARD · FY2019–2024
A2: Exploratory Data Analysis | Source: DATA_TABLE sheet | All values in USD millions
A4: TOTAL EXPORT VALUE | D4: TOTAL IMPORT VALUE | G4: TRADE SURPLUS | J4: TOP EXPORT | M4: TOP PARTNER | P4: NICKEL CAGR
A5: =SUMIF([1]DATA_TABLE!C2:C265,"Export",[1]DATA_TABLE!H2:H265) -> 379518 | D5: =SUMIF([1]DATA_TABLE!C2:C265,"Import",[1]DATA_TABLE!H2:H265) -> 273070 | G5: =SUMIF([1]DATA_TABLE!C2:C265,"Export",[1]DATA_TABLE!H2:H265)-SUMIF([1]DATA_TABLE!C2:C265,"Import",[1]DATA_TABLE!H2:H265) -> 106448 | J5: Coal & Nickel | M5: China | P5: =IFERROR((SUMIFS([1]DATA_TABLE!H2:H265,[1]DATA_TABLE!D2:D265,"Nickel Products",[1]DATA_TABLE!B2:B265,2024)/SUMIFS([1]DATA_TABLE!H2:H265,[1]DATA_TABLE!D2:D265,"Nickel Products",[1]DATA_TABLE!B2:B265,2019))^(1/5)-1,0) -> 0.3634017
A6: USD M | D6: USD M | G6: USD M | J6: by value | M6: 30%+ share | P6: 2019–24
A8: Annual Trade | E8: By Commodity | I8: By Partner | M8: Nickel Trend
A9: Year | B9: Exports | C9: Imports | E9: Commodity | F9: Exports | G9: Imports | I9: Partner | J9: Exports | K9: Imports | M9: Year | N9: Nickel Export
A10: 2019 | B10: =SUMIFS([1]DATA_TABLE!H2:H265,[1]DATA_TABLE!C2:C265,"Export",[1]DATA_TABLE!B2:B265,A10) -> 47442 | C10: =SUMIFS([1]DATA_TABLE!H2:H265,[1]DATA_TABLE!C2:C265,"Import",[1]DATA_TABLE!B2:B265,A10) -> 41620 | E10: Palm Oil | F10: =SUMIFS([1]DATA_TABLE!H2:H265,[1]DATA_TABLE!D2:D265,E10,[1]DATA_TABLE!C2:C265,"Export") -> 88270 | G10: =SUMIFS([1]DATA_TABLE!H2:H265,[1]DATA_TABLE!D2:D265,E10,[1]DATA_TABLE!C2:C265,"Import") -> 0 | I10: China | J10: =SUMIFS([1]DATA_TABLE!H2:H265,[1]DATA_TABLE!F2:F265,I10,[1]DATA_TABLE!C2:C265,"Export") -> 166040 | K10: =SUMIFS([1]DATA_TABLE!H2:H265,[1]DATA_TABLE!F2:F265,I10,[1]DATA_TABLE!C2:C265,"Import") -> 101860 | M10: 2019 | N10: =SUMIFS([1]DATA_TABLE!H2:H265,[1]DATA_TABLE!D2:D265,"Nickel Products",[1]DATA_TABLE!B2:B265,M10) -> 4880
A11: 2020 | B11: =SUMIFS([1]DATA_TABLE!H2:H265,[1]DATA_TABLE!C2:C265,"Export",[1]DATA_TABLE!B2:B265,A11) -> 37208 | C11: =SUMIFS([1]DATA_TABLE!H2:H265,[1]DATA_TABLE!C2:C265,"Import",[1]DATA_TABLE!B2:B265,A11) -> 32570 | E11: Coal | F11: =SUMIFS([1]DATA_TABLE!H2:H265,[1]DATA_TABLE!D2:D265,E11,[1]DATA_TABLE!C2:C265,"Export") -> 148610 | G11: =SUMIFS([1]DATA_TABLE!H2:H265,[1]DATA_TABLE!D2:D265,E11,[1]DATA_TABLE!C2:C265,"Import") -> 0 | I11: India | J11: =SUMIFS([1]DATA_TABLE!H2:H265,[1]DATA_TABLE!F2:F265,I11,[1]DATA_TABLE!C2:C265,"Export") -> 66950 | K11: =SUMIFS([1]DATA_TABLE!H2:H265,[1]DATA_TABLE!F2:F265,I11,[1]DATA_TABLE!C2:C265,"Import") -> 0 | M11: 2020 | N11: =SUMIFS([1]DATA_TABLE!H2:H265,[1]DATA_TABLE!D2:D265,"Nickel Products",[1]DATA_TABLE!B2:B265,M11) -> 5790
A12: 2021 | B12: =SUMIFS([1]DATA_TABLE!H2:H265,[1]DATA_TABLE!C2:C265,"Export",[1]DATA_TABLE!B2:B265,A12) -> 57636 | C12: =SUMIFS([1]DATA_TABLE!H2:H265,[1]DATA_TABLE!C2:C265,"Import",[1]DATA_TABLE!B2:B265,A12) -> 43060 | E12: Nickel Products | F12: =SUMIFS([1]DATA_TABLE!H2:H265,[1]DATA_TABLE!D2:D265,E12,[1]DATA_TABLE!C2:C265,"Export") -> 79130 | G12: =SUMIFS([1]DATA_TABLE!H2:H265,[1]DATA_TABLE!D2:D265,E12,[1]DATA_TABLE!C2:C265,"Import") -> 0 | I12: Japan | J12: =SUMIFS([1]DATA_TABLE!H2:H265,[1]DATA_TABLE!F2:F265,I12,[1]DATA_TABLE!C2:C265,"Export") -> 53254 | K12: =SUMIFS([1]DATA_TABLE!H2:H265,[1]DATA_TABLE!F2:F265,I12,[1]DATA_TABLE!C2:C265,"Import") -> 35760 | M12: 2021 | N12: =SUMIFS([1]DATA_TABLE!H2:H265,[1]DATA_TABLE!D2:D265,"Nickel Products",[1]DATA_TABLE!B2:B265,M12) -> 9220
A13: 2022 | B13: =SUMIFS([1]DATA_TABLE!H2:H265,[1]DATA_TABLE!C2:C265,"Export",[1]DATA_TABLE!B2:B265,A13) -> 86916 | C13: =SUMIFS([1]DATA_TABLE!H2:H265,[1]DATA_TABLE!C2:C265,"Import",[1]DATA_TABLE!B2:B265,A13) -> 53770 | E13: Rubber | F13: =SUMIFS([1]DATA_TABLE!H2:H265,[1]DATA_TABLE!D2:D265,E13,[1]DATA_TABLE!C2:C265,"Export") -> 20330 | G13: =SUMIFS([1]DATA_TABLE!H2:H265,[1]DATA_TABLE!D2:D265,E13,[1]DATA_TABLE!C2:C265,"Import") -> 0 | I13: Singapore | J13: =SUMIFS([1]DATA_TABLE!H2:H265,[1]DATA_TABLE!F2:F265,I13,[1]DATA_TABLE!C2:C265,"Export") -> 10520 | K13: =SUMIFS([1]DATA_TABLE!H2:H265,[1]DATA_TABLE!F2:F265,I13,[1]DATA_TABLE!C2:C265,"Import") -> 50520 | M13: 2022 | N13: =SUMIFS([1]DATA_TABLE!H2:H265,[1]DATA_TABLE!D2:D265,"Nickel Products",[1]DATA_TABLE!B2:B265,M13) -> 15270
A14: 2023 | B14: =SUMIFS([1]DATA_TABLE!H2:H265,[1]DATA_TABLE!C2:C265,"Export",[1]DATA_TABLE!B2:B265,A14) -> 75926 | C14: =SUMIFS([1]DATA_TABLE!H2:H265,[1]DATA_TABLE!C2:C265,"Import",[1]DATA_TABLE!B2:B265,A14) -> 48540 | E14: Crude Oil | F14: =SUMIFS([1]DATA_TABLE!H2:H265,[1]DATA_TABLE!D2:D265,E14,[1]DATA_TABLE!C2:C265,"Export") -> 37720 | G14: =SUMIFS([1]DATA_TABLE!H2:H265,[1]DATA_TABLE!D2:D265,E14,[1]DATA_TABLE!C2:C265,"Import") -> 0 | I14: South Korea | J14: =SUMIFS([1]DATA_TABLE!H2:H265,[1]DATA_TABLE!F2:F265,I14,[1]DATA_TABLE!C2:C265,"Export") -> 30340 | K14: =SUMIFS([1]DATA_TABLE!H2:H265,[1]DATA_TABLE!F2:F265,I14,[1]DATA_TABLE!C2:C265,"Import") -> 17260 | M14: 2023 | N14: =SUMIFS([1]DATA_TABLE!H2:H265,[1]DATA_TABLE!D2:D265,"Nickel Products",[1]DATA_TABLE!B2:B265,M14) -> 20980
A15: 2024 | B15: =SUMIFS([1]DATA_TABLE!H2:H265,[1]DATA_TABLE!C2:C265,"Export",[1]DATA_TABLE!B2:B265,A15) -> 74390 | C15: =SUMIFS([1]DATA_TABLE!H2:H265,[1]DATA_TABLE!C2:C265,"Import",[1]DATA_TABLE!B2:B265,A15) -> 53510 | E15: Coffee | F15: =SUMIFS([1]DATA_TABLE!H2:H265,[1]DATA_TABLE!D2:D265,E15,[1]DATA_TABLE!C2:C265,"Export") -> 5458 | G15: =SUMIFS([1]DATA_TABLE!H2:H265,[1]DATA_TABLE!D2:D265,E15,[1]DATA_TABLE!C2:C265,"Import") -> 0 | I15: USA | J15: =SUMIFS([1]DATA_TABLE!H2:H265,[1]DATA_TABLE!F2:F265,I15,[1]DATA_TABLE!C2:C265,"Export") -> 7908 | K15: =SUMIFS([1]DATA_TABLE!H2:H265,[1]DATA_TABLE!F2:F265,I15,[1]DATA_TABLE!C2:C265,"Import") -> 16140 | M15: 2024 | N15: =SUMIFS([1]DATA_TABLE!H2:H265,[1]DATA_TABLE!D2:D265,"Nickel Products",[1]DATA_TABLE!B2:B265,M15) -> 22990
E16: Electronics | F16: =SUMIFS([1]DATA_TABLE!H2:H265,[1]DATA_TABLE!D2:D265,E16,[1]DATA_TABLE!C2:C265,"Export") -> 0 | G16: =SUMIFS([1]DATA_TABLE!H2:H265,[1]DATA_TABLE!D2:D265,E16,[1]DATA_TABLE!C2:C265,"Import") -> 71260 | I16: EU | J16: =SUMIFS([1]DATA_TABLE!H2:H265,[1]DATA_TABLE!F2:F265,I16,[1]DATA_TABLE!C2:C265,"Export") -> 16356 | K16: =SUMIFS([1]DATA_TABLE!H2:H265,[1]DATA_TABLE!F2:F265,I16,[1]DATA_TABLE!C2:C265,"Import") -> 0
E17: Machinery | F17: =SUMIFS([1]DATA_TABLE!H2:H265,[1]DATA_TABLE!D2:D265,E17,[1]DATA_TABLE!C2:C265,"Export") -> 0 | G17: =SUMIFS([1]DATA_TABLE!H2:H265,[1]DATA_TABLE!D2:D265,E17,[1]DATA_TABLE!C2:C265,"Import") -> 84900 | I17: Malaysia | J17: =SUMIFS([1]DATA_TABLE!H2:H265,[1]DATA_TABLE!F2:F265,I17,[1]DATA_TABLE!C2:C265,"Export") -> 6090 | K17: =SUMIFS([1]DATA_TABLE!H2:H265,[1]DATA_TABLE!F2:F265,I17,[1]DATA_TABLE!C2:C265,"Import") -> 11640
E18: Petroleum Products | F18: =SUMIFS([1]DATA_TABLE!H2:H265,[1]DATA_TABLE!D2:D265,E18,[1]DATA_TABLE!C2:C265,"Export") -> 0 | G18: =SUMIFS([1]DATA_TABLE!H2:H265,[1]DATA_TABLE!D2:D265,E18,[1]DATA_TABLE!C2:C265,"Import") -> 43220 | I18: Germany | J18: =SUMIFS([1]DATA_TABLE!H2:H265,[1]DATA_TABLE!F2:F265,I18,[1]DATA_TABLE!C2:C265,"Export") -> 0 | K18: =SUMIFS([1]DATA_TABLE!H2:H265,[1]DATA_TABLE!F2:F265,I18,[1]DATA_TABLE!C2:C265,"Import") -> 16780
E19: Steel | F19: =SUMIFS([1]DATA_TABLE!H2:H265,[1]DATA_TABLE!D2:D265,E19,[1]DATA_TABLE!C2:C265,"Export") -> 0 | G19: =SUMIFS([1]DATA_TABLE!H2:H265,[1]DATA_TABLE!D2:D265,E19,[1]DATA_TABLE!C2:C265,"Import") -> 35040 | I19: Australia | J19: =SUMIFS([1]DATA_TABLE!H2:H265,[1]DATA_TABLE!F2:F265,I19,[1]DATA_TABLE!C2:C265,"Export") -> 0 | K19: =SUMIFS([1]DATA_TABLE!H2:H265,[1]DATA_TABLE!F2:F265,I19,[1]DATA_TABLE!C2:C265,"Import") -> 7150
E20: Wheat | F20: =SUMIFS([1]DATA_TABLE!H2:H265,[1]DATA_TABLE!D2:D265,E20,[1]DATA_TABLE!C2:C265,"Export") -> 0 | G20: =SUMIFS([1]DATA_TABLE!H2:H265,[1]DATA_TABLE!D2:D265,E20,[1]DATA_TABLE!C2:C265,"Import") -> 14170
E21: Chemicals | F21: =SUMIFS([1]DATA_TABLE!H2:H265,[1]DATA_TABLE!D2:D265,E21,[1]DATA_TABLE!C2:C265,"Export") -> 0 | G21: =SUMIFS([1]DATA_TABLE!H2:H265,[1]DATA_TABLE!D2:D265,E21,[1]DATA_TABLE!C2:C265,"Import") -> 24480

Sheet DATA PROFILE
A1: STEP 1 · DATA PROFILE
A2: Data profiling reveals the shape, completeness, and distribution of your dataset before any analysis begins.
A4: A · COLUMN PROFILE — Data Types, Null Counts, Unique Values
A5: Column | C5: Data Type | E5: Non-Null Count | F5: Null Count | G5: Unique Values | H5: Sample Values | L5: Notes
A6: Record_ID | C6: Text (ID) | E6: =COUNTA('RAW DATA'!A4:A267) -> 264 | F6: 0 | G6: 264 | H6: IDN-0001 … IDN-0264 | L6: Primary key — unique per record
A7: Year | C7: Integer | E7: =COUNTA('RAW DATA'!B4:B267) -> 264 | F7: 0 | G7: 6 | H7: 2019, 2020 … 2024 | L7: Annual data, no gaps
A8: Trade_Type | C8: Categorical | E8: =COUNTA('RAW DATA'!C4:C267) -> 264 | F8: 0 | G8: 2 | H8: Export, Import | L8: Balanced: 132 each
A9: Commodity | C9: Categorical | E9: =COUNTA('RAW DATA'!D4:D267) -> 264 | F9: 0 | G9: 12 | H9: Palm Oil, Coal … | L9: 6 export + 6 import commodities
A10: HS_Code | C10: Text (Code) | E10: =COUNTA('RAW DATA'!E4:E267) -> 264 | F10: 0 | G10: 6 | H10: 15, 27, 40 … | L10: Simplified 2-digit HS codes
A11: Trading_Partner | C11: Categorical | E11: =COUNTA('RAW DATA'!F4:F267) -> 264 | F11: 0 | G11: 15 | H11: China, India … | L11: 15 unique trading partners
A12: Region | C12: Categorical | E12: =COUNTA('RAW DATA'!G4:G267) -> 264 | F12: 0 | G12: 5 | H12: East Asia, Europe … | L12: Geographic grouping
A13: Trade_Value_USD_M | C13: Numeric (USD M) | E13: =COUNTA('RAW DATA'!H4:H267) -> 264 | F13: 0 | G13: n/a | H13: Continuous | L13: USD millions — all records populated
A14: Volume_kMT | C14: Numeric (kMT) | E14: =COUNTA('RAW DATA'!I4:I267) -> 264 | F14: 0 | G14: n/a | H14: Continuous | L14: Thousand metric tonnes (derived)
A15: Unit_Price_USD_MT | C15: Numeric (USD/T) | E15: =COUNTA('RAW DATA'!J4:J267) -> 264 | F15: 0 | G15: n/a | H15: Continuous | L15: Price per metric tonne (varies by year)
A16: Logistics_Mode | C16: Categorical | E16: =COUNTA('RAW DATA'!K4:K267) -> 264 | F16: 0 | G16: 2 | H16: Sea, Air/Sea | L16: All sea freight dominant
A19: B · NUMERIC SUMMARY — Descriptive Statistics for Key Measures
A20: Metric | C20: MIN | D20: MAX | E20: MEAN | F20: MEDIAN | G20: STDEV | H20: P25 | I20: P75 | J20: CV% | K20: Skew Note | L20: Analyst Takeaway
A21: Trade_Value (USD M) | C21: =MIN('RAW DATA'!H4:H267) -> 112 | D21: =MAX('RAW DATA'!H4:H267) -> 18200 | E21: =AVERAGE('RAW DATA'!H4:H267) -> 2471.9242 | F21: =MEDIAN('RAW DATA'!H4:H267) -> 1740 | G21: =STDEV('RAW DATA'!H4:H267) -> 2450.594 | H21: =PERCENTILE('RAW DATA'!H4:H267,0.25) -> 1015 | I21: =PERCENTILE('RAW DATA'!H4:H267,0.75) -> 2942.5 | J21: =IFERROR(STDEV('RAW DATA'!H4:H267)/AVERAGE('RAW DATA'!H4:H267),0) -> 0.99137101 | K21: High spread; coal/nickel outliers push mean above median
A22: Volume (kMT) | C22: =MIN('RAW DATA'!I4:I267) -> 30 | D22: =MAX('RAW DATA'!I4:I267) -> 87200 | E22: =AVERAGE('RAW DATA'!I4:I267) -> 5583.9841 | F22: =MEDIAN('RAW DATA'!I4:I267) -> 1388.9 | G22: =STDEV('RAW DATA'!I4:I267) -> 12704.477 | H22: =PERCENTILE('RAW DATA'!I4:I267,0.25) -> 438.825 | I22: =PERCENTILE('RAW DATA'!I4:I267,0.75) -> 3183.625 | J22: =IFERROR(STDEV('RAW DATA'!I4:I267)/AVERAGE('RAW DATA'!I4:I267),0) -> 2.2751636 | K22: Right-skewed; coal volumes dominate upper quartile
A23: Unit Price (USD/MT) | C23: =MIN('RAW DATA'!J4:J267) -> 65 | D23: =MAX('RAW DATA'!J4:J267) -> 26000 | E23: =AVERAGE('RAW DATA'!J4:J267) -> 2913.5038 | F23: =MEDIAN('RAW DATA'!J4:J267) -> 1100 | G23: =STDEV('RAW DATA'!J4:J267) -> 4713.9189 | H23: =PERCENTILE('RAW DATA'!J4:J267,0.25) -> 640 | I23: =PERCENTILE('RAW DATA'!J4:J267,0.75) -> 3300 | J23: =IFERROR(STDEV('RAW DATA'!J4:J267)/AVERAGE('RAW DATA'!J4:J267),0) -> 1.6179553 | K23: Bimodal: low bulk (coal/wheat) vs high value (nickel, electronics)
A25: C · CATEGORICAL FREQUENCIES — Trade Type & Commodity Distribution
A26: Trade Type | B26: Count | C26: % of Total | E26: Commodity | G26: Count | H26: Exports | I26: Imports | J26: % of Total
A27: Export | B27: =COUNTIF('RAW DATA'!C4:C267,"Export") -> 132 | C27: =COUNTIF('RAW DATA'!C4:C267,"Export")/COUNTA('RAW DATA'!C4:C267) -> 0.5 | E27: Palm Oil | G27: =COUNTIF('RAW DATA'!D4:D267,E27) -> 30 | H27: =COUNTIFS('RAW DATA'!D4:D267,E27,'RAW DATA'!C4:C267,"Export") -> 30 | I27: =COUNTIFS('RAW DATA'!D4:D267,E27,'RAW DATA'!C4:C267,"Import") -> 0 | J27: =IFERROR(G27/COUNTA('RAW DATA'!D4:D267),0) -> 0.11363636
A28: Import | B28: =COUNTIF('RAW DATA'!C4:C267,"Import") -> 132 | C28: =COUNTIF('RAW DATA'!C4:C267,"Import")/COUNTA('RAW DATA'!C4:C267) -> 0.5 | E28: Coal | G28: =COUNTIF('RAW DATA'!D4:D267,E28) -> 30 | H28: =COUNTIFS('RAW DATA'!D4:D267,E28,'RAW DATA'!C4:C267,"Export") -> 30 | I28: =COUNTIFS('RAW DATA'!D4:D267,E28,'RAW DATA'!C4:C267,"Import") -> 0 | J28: =IFERROR(G28/COUNTA('RAW DATA'!D4:D267),0) -> 0.11363636
E29: Nickel Products | G29: =COUNTIF('RAW DATA'!D4:D267,E29) -> 18 | H29: =COUNTIFS('RAW DATA'!D4:D267,E29,'RAW DATA'!C4:C267,"Export") -> 18 | I29: =COUNTIFS('RAW DATA'!D4:D267,E29,'RAW DATA'!C4:C267,"Import") -> 0 | J29: =IFERROR(G29/COUNTA('RAW DATA'!D4:D267),0) -> 0.068181818
E30: Rubber | G30: =COUNTIF('RAW DATA'!D4:D267,E30) -> 18 | H30: =COUNTIFS('RAW DATA'!D4:D267,E30,'RAW DATA'!C4:C267,"Export") -> 18 | I30: =COUNTIFS('RAW DATA'!D4:D267,E30,'RAW DATA'!C4:C267,"Import") -> 0 | J30: =IFERROR(G30/COUNTA('RAW DATA'!D4:D267),0) -> 0.068181818
E31: Crude Oil | G31: =COUNTIF('RAW DATA'!D4:D267,E31) -> 18 | H31: =COUNTIFS('RAW DATA'!D4:D267,E31,'RAW DATA'!C4:C267,"Export") -> 18 | I31: =COUNTIFS('RAW DATA'!D4:D267,E31,'RAW DATA'!C4:C267,"Import") -> 0 | J31: =IFERROR(G31/COUNTA('RAW DATA'!D4:D267),0) -> 0.068181818
E32: Coffee | G32: =COUNTIF('RAW DATA'!D4:D267,E32) -> 18 | H32: =COUNTIFS('RAW DATA'!D4:D267,E32,'RAW DATA'!C4:C267,"Export") -> 18 | I32: =COUNTIFS('RAW DATA'!D4:D267,E32,'RAW DATA'!C4:C267,"Import") -> 0 | J32: =IFERROR(G32/COUNTA('RAW DATA'!D4:D267),0) -> 0.068181818
E33: Electronics | G33: =COUNTIF('RAW DATA'!D4:D267,E33) -> 30 | H33: =COUNTIFS('RAW DATA'!D4:D267,E33,'RAW DATA'!C4:C267,"Export") -> 0 | I33: =COUNTIFS('RAW DATA'!D4:D267,E33,'RAW DATA'!C4:C267,"Import") -> 30 | J33: =IFERROR(G33/COUNTA('RAW DATA'!D4:D267),0) -> 0.11363636
E34: Machinery | G34: =COUNTIF('RAW DATA'!D4:D267,E34) -> 30 | H34: =COUNTIFS('RAW DATA'!D4:D267,E34,'RAW DATA'!C4:C267,"Export") -> 0 | I34: =COUNTIFS('RAW DATA'!D4:D267,E34,'RAW DATA'!C4:C267,"Import") -> 30 | J34: =IFERROR(G34/COUNTA('RAW DATA'!D4:D267),0) -> 0.11363636
E35: Petroleum Products | G35: =COUNTIF('RAW DATA'!D4:D267,E35) -> 18 | H35: =COUNTIFS('RAW DATA'!D4:D267,E35,'RAW DATA'!C4:C267,"Export") -> 0 | I35: =COUNTIFS('RAW DATA'!D4:D267,E35,'RAW DATA'!C4:C267,"Import") -> 18 | J35: =IFERROR(G35/COUNTA('RAW DATA'!D4:D267),0) -> 0.068181818
E36: Steel | G36: =COUNTIF('RAW DATA'!D4:D267,E36) -> 18 | H36: =COUNTIFS('RAW DATA'!D4:D267,E36,'RAW DATA'!C4:C267,"Export") -> 0 | I36: =COUNTIFS('RAW DATA'!D4:D267,E36,'RAW DATA'!C4:C267,"Import") -> 18 | J36: =IFERROR(G36/COUNTA('RAW DATA'!D4:D267),0) -> 0.068181818
E37: Wheat | G37: =COUNTIF('RAW DATA'!D4:D267,E37) -> 18 | H37: =COUNTIFS('RAW DATA'!D4:D267,E37,'RAW DATA'!C4:C267,"Export") -> 0 | I37: =COUNTIFS('RAW DATA'!D4:D267,E37,'RAW DATA'!C4:C267,"Import") -> 18 | J37: =IFERROR(G37/COUNTA('RAW DATA'!D4:D267),0) -> 0.068181818
E38: Chemicals | G38: =COUNTIF('RAW DATA'!D4:D267,E38) -> 18 | H38: =COUNTIFS('RAW DATA'!D4:D267,E38,'RAW DATA'!C4:C267,"Export") -> 0 | I38: =COUNTIFS('RAW DATA'!D4:D267,E38,'RAW DATA'!C4:C267,"Import") -> 18 | J38: =IFERROR(G38/COUNTA('RAW DATA'!D4:D267),0) -> 0.068181818

Sheet UNIVARIATE
A1: STEP 2 · UNIVARIATE ANALYSIS — One Variable at a Time
A2: Examine each variable individually to understand its distribution before looking at relationships between variables.
A4: U1 · TRADE VALUE (USD M) BY COMMODITY — All Years Combined | I4: U3 · TRADING PARTNER FREQUENCY
A5: Commodity | B5: Type | C5: Total Value | D5: Mean/Record | E5: Min | F5: Max | G5: Std Dev | I5: Partner | J5: Records | K5: % of Total | L5: Export Records | M5: Import Records
A6: Palm Oil | B6: Export | C6: =SUMIF('RAW DATA'!D4:D267,A6,'RAW DATA'!H4:H267) -> 88270 | D6: =IFERROR(AVERAGEIF('RAW DATA'!D4:D267,A6,'RAW DATA'!H4:H267),0) -> 2942.3333 | E6: =IFERROR(MIN(IF('RAW DATA'!D4:D267=A6,'RAW DATA'!H4:H267)),0) -> 112 | F6: =IFERROR(MAX(IF('RAW DATA'!D4:D267=A6,'RAW DATA'!H4:H267)),0) -> 18200 | G6: =IFERROR(STDEV(IF('RAW DATA'!D4:D267=A6,'RAW DATA'!H4:H267)),0) -> 2450.594 | I6: China | J6: =COUNTIF('RAW DATA'!F4:F267,I6) -> 54 | K6: =IFERROR(COUNTIF('RAW DATA'!F4:F267,I6)/COUNTA('RAW DATA'!F4:F267),0) -> 0.20454545 | L6: =COUNTIFS('RAW DATA'!F4:F267,I6,'RAW DATA'!C4:C267,"Export") -> 30 | M6: =COUNTIFS('RAW DATA'!F4:F267,I6,'RAW DATA'!C4:C267,"Import") -> 24
A7: Coal | B7: Export | C7: =SUMIF('RAW DATA'!D4:D267,A7,'RAW DATA'!H4:H267) -> 148610 | D7: =IFERROR(AVERAGEIF('RAW DATA'!D4:D267,A7,'RAW DATA'!H4:H267),0) -> 4953.6667 | E7: =IFERROR(MIN(IF('RAW DATA'!D4:D267=A7,'RAW DATA'!H4:H267)),0) -> 0 | F7: =IFERROR(MAX(IF('RAW DATA'!D4:D267=A7,'RAW DATA'!H4:H267)),0) -> 0 | G7: =IFERROR(STDEV(IF('RAW DATA'!D4:D267=A7,'RAW DATA'!H4:H267)),0) -> 0 | I7: India | J7: =COUNTIF('RAW DATA'!F4:F267,I7) -> 12 | K7: =IFERROR(COUNTIF('RAW DATA'!F4:F267,I7)/COUNTA('RAW DATA'!F4:F267),0) -> 0.045454545 | L7: =COUNTIFS('RAW DATA'!F4:F267,I7,'RAW DATA'!C4:C267,"Export") -> 12 | M7: =COUNTIFS('RAW DATA'!F4:F267,I7,'RAW DATA'!C4:C267,"Import") -> 0
A8: Nickel Products | B8: Export | C8: =SUMIF('RAW DATA'!D4:D267,A8,'RAW DATA'!H4:H267) -> 79130 | D8: =IFERROR(AVERAGEIF('RAW DATA'!D4:D267,A8,'RAW DATA'!H4:H267),0) -> 4396.1111 | E8: =IFERROR(MIN(IF('RAW DATA'!D4:D267=A8,'RAW DATA'!H4:H267)),0) -> 0 | F8: =IFERROR(MAX(IF('RAW DATA'!D4:D267=A8,'RAW DATA'!H4:H267)),0) -> 0 | G8: =IFERROR(STDEV(IF('RAW DATA'!D4:D267=A8,'RAW DATA'!H4:H267)),0) -> 0 | I8: Japan | J8: =COUNTIF('RAW DATA'!F4:F267,I8) -> 48 | K8: =IFERROR(COUNTIF('RAW DATA'!F4:F267,I8)/COUNTA('RAW DATA'!F4:F267),0) -> 0.18181818 | L8: =COUNTIFS('RAW DATA'!F4:F267,I8,'RAW DATA'!C4:C267,"Export") -> 30 | M8: =COUNTIFS('RAW DATA'!F4:F267,I8,'RAW DATA'!C4:C267,"Import") -> 18
A9: Rubber | B9: Export | C9: =SUMIF('RAW DATA'!D4:D267,A9,'RAW DATA'!H4:H267) -> 20330 | D9: =IFERROR(AVERAGEIF('RAW DATA'!D4:D267,A9,'RAW DATA'!H4:H267),0) -> 1129.4444 | E9: =IFERROR(MIN(IF('RAW DATA'!D4:D267=A9,'RAW DATA'!H4:H267)),0) -> 0 | F9: =IFERROR(MAX(IF('RAW DATA'!D4:D267=A9,'RAW DATA'!H4:H267)),0) -> 0 | G9: =IFERROR(STDEV(IF('RAW DATA'!D4:D267=A9,'RAW DATA'!H4:H267)),0) -> 0 | I9: USA | J9: =COUNTIF('RAW DATA'!F4:F267,I9) -> 24 | K9: =IFERROR(COUNTIF('RAW DATA'!F4:F267,I9)/COUNTA('RAW DATA'!F4:F267),0) -> 0.090909091 | L9: =COUNTIFS('RAW DATA'!F4:F267,I9,'RAW DATA'!C4:C267,"Export") -> 12 | M9: =COUNTIFS('RAW DATA'!F4:F267,I9,'RAW DATA'!C4:C267,"Import") -> 12
A10: Crude Oil | B10: Export | C10: =SUMIF('RAW DATA'!D4:D267,A10,'RAW DATA'!H4:H267) -> 37720 | D10: =IFERROR(AVERAGEIF('RAW DATA'!D4:D267,A10,'RAW DATA'!H4:H267),0) -> 2095.5556 | E10: =IFERROR(MIN(IF('RAW DATA'!D4:D267=A10,'RAW DATA'!H4:H267)),0) -> 0 | F10: =IFERROR(MAX(IF('RAW DATA'!D4:D267=A10,'RAW DATA'!H4:H267)),0) -> 0 | G10: =IFERROR(STDEV(IF('RAW DATA'!D4:D267=A10,'RAW DATA'!H4:H267)),0) -> 0 | I10: Singapore | J10: =COUNTIF('RAW DATA'!F4:F267,I10) -> 30 | K10: =IFERROR(COUNTIF('RAW DATA'!F4:F267,I10)/COUNTA('RAW DATA'!F4:F267),0) -> 0.11363636 | L10: =COUNTIFS('RAW DATA'!F4:F267,I10,'RAW DATA'!C4:C267,"Export") -> 6 | M10: =COUNTIFS('RAW DATA'!F4:F267,I10,'RAW DATA'!C4:C267,"Import") -> 24
A11: Coffee | B11: Export | C11: =SUMIF('RAW DATA'!D4:D267,A11,'RAW DATA'!H4:H267) -> 5458 | D11: =IFERROR(AVERAGEIF('RAW DATA'!D4:D267,A11,'RAW DATA'!H4:H267),0) -> 303.22222 | E11: =IFERROR(MIN(IF('RAW DATA'!D4:D267=A11,'RAW DATA'!H4:H267)),0) -> 0 | F11: =IFERROR(MAX(IF('RAW DATA'!D4:D267=A11,'RAW DATA'!H4:H267)),0) -> 0 | G11: =IFERROR(STDEV(IF('RAW DATA'!D4:D267=A11,'RAW DATA'!H4:H267)),0) -> 0 | I11: South Korea | J11: =COUNTIF('RAW DATA'!F4:F267,I11) -> 24 | K11: =IFERROR(COUNTIF('RAW DATA'!F4:F267,I11)/COUNTA('RAW DATA'!F4:F267),0) -> 0.090909091 | L11: =COUNTIFS('RAW DATA'!F4:F267,I11,'RAW DATA'!C4:C267,"Export") -> 12 | M11: =COUNTIFS('RAW DATA'!F4:F267,I11,'RAW DATA'!C4:C267,"Import") -> 12
A12: Electronics | B12: Import | C12: =SUMIF('RAW DATA'!D4:D267,A12,'RAW DATA'!H4:H267) -> 71260 | D12: =IFERROR(AVERAGEIF('RAW DATA'!D4:D267,A12,'RAW DATA'!H4:H267),0) -> 2375.3333 | E12: =IFERROR(MIN(IF('RAW DATA'!D4:D267=A12,'RAW DATA'!H4:H267)),0) -> 0 | F12: =IFERROR(MAX(IF('RAW DATA'!D4:D267=A12,'RAW DATA'!H4:H267)),0) -> 0 | G12: =IFERROR(STDEV(IF('RAW DATA'!D4:D267=A12,'RAW DATA'!H4:H267)),0) -> 0 | I12: EU | J12: =COUNTIF('RAW DATA'!F4:F267,I12) -> 12 | K12: =IFERROR(COUNTIF('RAW DATA'!F4:F267,I12)/COUNTA('RAW DATA'!F4:F267),0) -> 0.045454545 | L12: =COUNTIFS('RAW DATA'!F4:F267,I12,'RAW DATA'!C4:C267,"Export") -> 12 | M12: =COUNTIFS('RAW DATA'!F4:F267,I12,'RAW DATA'!C4:C267,"Import") -> 0
A13: Machinery | B13: Import | C13: =SUMIF('RAW DATA'!D4:D267,A13,'RAW DATA'!H4:H267) -> 84900 | D13: =IFERROR(AVERAGEIF('RAW DATA'!D4:D267,A13,'RAW DATA'!H4:H267),0) -> 2830 | E13: =IFERROR(MIN(IF('RAW DATA'!D4:D267=A13,'RAW DATA'!H4:H267)),0) -> 0 | F13: =IFERROR(MAX(IF('RAW DATA'!D4:D267=A13,'RAW DATA'!H4:H267)),0) -> 0 | G13: =IFERROR(STDEV(IF('RAW DATA'!D4:D267=A13,'RAW DATA'!H4:H267)),0) -> 0 | I13: Malaysia | J13: =COUNTIF('RAW DATA'!F4:F267,I13) -> 12 | K13: =IFERROR(COUNTIF('RAW DATA'!F4:F267,I13)/COUNTA('RAW DATA'!F4:F267),0) -> 0.045454545 | L13: =COUNTIFS('RAW DATA'!F4:F267,I13,'RAW DATA'!C4:C267,"Export") -> 6 | M13: =COUNTIFS('RAW DATA'!F4:F267,I13,'RAW DATA'!C4:C267,"Import") -> 6
A14: Petroleum Products | B14: Import | C14: =SUMIF('RAW DATA'!D4:D267,A14,'RAW DATA'!H4:H267) -> 43220 | D14: =IFERROR(AVERAGEIF('RAW DATA'!D4:D267,A14,'RAW DATA'!H4:H267),0) -> 2401.1111 | E14: =IFERROR(MIN(IF('RAW DATA'!D4:D267=A14,'RAW DATA'!H4:H267)),0) -> 0 | F14: =IFERROR(MAX(IF('RAW DATA'!D4:D267=A14,'RAW DATA'!H4:H267)),0) -> 0 | G14: =IFERROR(STDEV(IF('RAW DATA'!D4:D267=A14,'RAW DATA'!H4:H267)),0) -> 0 | I14: Germany | J14: =COUNTIF('RAW DATA'!F4:F267,I14) -> 12 | K14: =IFERROR(COUNTIF('RAW DATA'!F4:F267,I14)/COUNTA('RAW DATA'!F4:F267),0) -> 0.045454545 | L14: =COUNTIFS('RAW DATA'!F4:F267,I14,'RAW DATA'!C4:C267,"Export") -> 0 | M14: =COUNTIFS('RAW DATA'!F4:F267,I14,'RAW DATA'!C4:C267,"Import") -> 12
A15: Steel | B15: Import | C15: =SUMIF('RAW DATA'!D4:D267,A15,'RAW DATA'!H4:H267) -> 35040 | D15: =IFERROR(AVERAGEIF('RAW DATA'!D4:D267,A15,'RAW DATA'!H4:H267),0) -> 1946.6667 | E15: =IFERROR(MIN(IF('RAW DATA'!D4:D267=A15,'RAW DATA'!H4:H267)),0) -> 0 | F15: =IFERROR(MAX(IF('RAW DATA'!D4:D267=A15,'RAW DATA'!H4:H267)),0) -> 0 | G15: =IFERROR(STDEV(IF('RAW DATA'!D4:D267=A15,'RAW DATA'!H4:H267)),0) -> 0 | I15: Pakistan | J15: =COUNTIF('RAW DATA'!F4:F267,I15) -> 6 | K15: =IFERROR(COUNTIF('RAW DATA'!F4:F267,I15)/COUNTA('RAW DATA'!F4:F267),0) -> 0.022727273 | L15: =COUNTIFS('RAW DATA'!F4:F267,I15,'RAW DATA'!C4:C267,"Export") -> 6 | M15: =COUNTIFS('RAW DATA'!F4:F267,I15,'RAW DATA'!C4:C267,"Import") -> 0
A16: Wheat | B16: Import | C16: =SUMIF('RAW DATA'!D4:D267,A16,'RAW DATA'!H4:H267) -> 14170 | D16: =IFERROR(AVERAGEIF('RAW DATA'!D4:D267,A16,'RAW DATA'!H4:H267),0) -> 787.22222 | E16: =IFERROR(MIN(IF('RAW DATA'!D4:D267=A16,'RAW DATA'!H4:H267)),0) -> 0 | F16: =IFERROR(MAX(IF('RAW DATA'!D4:D267=A16,'RAW DATA'!H4:H267)),0) -> 0 | G16: =IFERROR(STDEV(IF('RAW DATA'!D4:D267=A16,'RAW DATA'!H4:H267)),0) -> 0 | I16: Philippines | J16: =COUNTIF('RAW DATA'!F4:F267,I16) -> 6 | K16: =IFERROR(COUNTIF('RAW DATA'!F4:F267,I16)/COUNTA('RAW DATA'!F4:F267),0) -> 0.022727273 | L16: =COUNTIFS('RAW DATA'!F4:F267,I16,'RAW DATA'!C4:C267,"Export") -> 6 | M16: =COUNTIFS('RAW DATA'!F4:F267,I16,'RAW DATA'!C4:C267,"Import") -> 0
A17: Chemicals | B17: Import | C17: =SUMIF('RAW DATA'!D4:D267,A17,'RAW DATA'!H4:H267) -> 24480 | D17: =IFERROR(AVERAGEIF('RAW DATA'!D4:D267,A17,'RAW DATA'!H4:H267),0) -> 1360 | E17: =IFERROR(MIN(IF('RAW DATA'!D4:D267=A17,'RAW DATA'!H4:H267)),0) -> 0 | F17: =IFERROR(MAX(IF('RAW DATA'!D4:D267=A17,'RAW DATA'!H4:H267)),0) -> 0 | G17: =IFERROR(STDEV(IF('RAW DATA'!D4:D267=A17,'RAW DATA'!H4:H267)),0) -> 0 | I17: Australia | J17: =COUNTIF('RAW DATA'!F4:F267,I17) -> 6 | K17: =IFERROR(COUNTIF('RAW DATA'!F4:F267,I17)/COUNTA('RAW DATA'!F4:F267),0) -> 0.022727273 | L17: =COUNTIFS('RAW DATA'!F4:F267,I17,'RAW DATA'!C4:C267,"Export") -> 0 | M17: =COUNTIFS('RAW DATA'!F4:F267,I17,'RAW DATA'!C4:C267,"Import") -> 6
I18: Canada | J18: =COUNTIF('RAW DATA'!F4:F267,I18) -> 6 | K18: =IFERROR(COUNTIF('RAW DATA'!F4:F267,I18)/COUNTA('RAW DATA'!F4:F267),0) -> 0.022727273 | L18: =COUNTIFS('RAW DATA'!F4:F267,I18,'RAW DATA'!C4:C267,"Export") -> 0 | M18: =COUNTIFS('RAW DATA'!F4:F267,I18,'RAW DATA'!C4:C267,"Import") -> 6
I19: Saudi Arabia | J19: =COUNTIF('RAW DATA'!F4:F267,I19) -> 6 | K19: =IFERROR(COUNTIF('RAW DATA'!F4:F267,I19)/COUNTA('RAW DATA'!F4:F267),0) -> 0.022727273 | L19: =COUNTIFS('RAW DATA'!F4:F267,I19,'RAW DATA'!C4:C267,"Export") -> 0 | M19: =COUNTIFS('RAW DATA'!F4:F267,I19,'RAW DATA'!C4:C267,"Import") -> 6
A20: U2 · VOLUME (kMT) DESCRIPTIVE STATS — All Years | I20: Ukraine | J20: =COUNTIF('RAW DATA'!F4:F267,I20) -> 6 | K20: =IFERROR(COUNTIF('RAW DATA'!F4:F267,I20)/COUNTA('RAW DATA'!F4:F267),0) -> 0.022727273 | L20: =COUNTIFS('RAW DATA'!F4:F267,I20,'RAW DATA'!C4:C267,"Export") -> 0 | M20: =COUNTIFS('RAW DATA'!F4:F267,I20,'RAW DATA'!C4:C267,"Import") -> 6
A21: Commodity | B21: Type | C21: Total kMT | D21: Mean kMT | E21: Min kMT | F21: Max kMT | G21: YoY Volatility (STDEV)
A22: Palm Oil | B22: Export | C22: =SUMIF('RAW DATA'!D4:D267,A22,'RAW DATA'!I4:I267) -> 94752.1 | D22: =IFERROR(AVERAGEIF('RAW DATA'!D4:D267,A22,'RAW DATA'!I4:I267),0) -> 3158.4033 | E22: =IFERROR(MIN(IF('RAW DATA'!D4:D267=A22,'RAW DATA'!I4:I267)),0) -> 30 | F22: =IFERROR(MAX(IF('RAW DATA'!D4:D267=A22,'RAW DATA'!I4:I267)),0) -> 87200 | G22: =IFERROR(STDEV(IF('RAW DATA'!D4:D267=A22,'RAW DATA'!I4:I267)),0) -> 12704.477
A23: Coal | B23: Export | C23: =SUMIF('RAW DATA'!D4:D267,A23,'RAW DATA'!I4:I267) -> 1079813 | D23: =IFERROR(AVERAGEIF('RAW DATA'!D4:D267,A23,'RAW DATA'!I4:I267),0) -> 35993.767 | E23: =IFERROR(MIN(IF('RAW DATA'!D4:D267=A23,'RAW DATA'!I4:I267)),0) -> 0 | F23: =IFERROR(MAX(IF('RAW DATA'!D4:D267=A23,'RAW DATA'!I4:I267)),0) -> 0 | G23: =IFERROR(STDEV(IF('RAW DATA'!D4:D267=A23,'RAW DATA'!I4:I267)),0) -> 0
A24: Nickel Products | B24: Export | C24: =SUMIF('RAW DATA'!D4:D267,A24,'RAW DATA'!I4:I267) -> 4140.8 | D24: =IFERROR(AVERAGEIF('RAW DATA'!D4:D267,A24,'RAW DATA'!I4:I267),0) -> 230.04444 | E24: =IFERROR(MIN(IF('RAW DATA'!D4:D267=A24,'RAW DATA'!I4:I267)),0) -> 0 | F24: =IFERROR(MAX(IF('RAW DATA'!D4:D267=A24,'RAW DATA'!I4:I267)),0) -> 0 | G24: =IFERROR(STDEV(IF('RAW DATA'!D4:D267=A24,'RAW DATA'!I4:I267)),0) -> 0
A25: Rubber | B25: Export | C25: =SUMIF('RAW DATA'!D4:D267,A25,'RAW DATA'!I4:I267) -> 12672.5 | D25: =IFERROR(AVERAGEIF('RAW DATA'!D4:D267,A25,'RAW DATA'!I4:I267),0) -> 704.02778 | E25: =IFERROR(MIN(IF('RAW DATA'!D4:D267=A25,'RAW DATA'!I4:I267)),0) -> 0 | F25: =IFERROR(MAX(IF('RAW DATA'!D4:D267=A25,'RAW DATA'!I4:I267)),0) -> 0 | G25: =IFERROR(STDEV(IF('RAW DATA'!D4:D267=A25,'RAW DATA'!I4:I267)),0) -> 0
A26: Crude Oil | B26: Export | C26: =SUMIF('RAW DATA'!D4:D267,A26,'RAW DATA'!I4:I267) -> 56876 | D26: =IFERROR(AVERAGEIF('RAW DATA'!D4:D267,A26,'RAW DATA'!I4:I267),0) -> 3159.7778 | E26: =IFERROR(MIN(IF('RAW DATA'!D4:D267=A26,'RAW DATA'!I4:I267)),0) -> 0 | F26: =IFERROR(MAX(IF('RAW DATA'!D4:D267=A26,'RAW DATA'!I4:I267)),0) -> 0 | G26: =IFERROR(STDEV(IF('RAW DATA'!D4:D267=A26,'RAW DATA'!I4:I267)),0) -> 0
A27: Coffee | B27: Export | C27: =SUMIF('RAW DATA'!D4:D267,A27,'RAW DATA'!I4:I267) -> 2493.9 | D27: =IFERROR(AVERAGEIF('RAW DATA'!D4:D267,A27,'RAW DATA'!I4:I267),0) -> 138.55 | E27: =IFERROR(MIN(IF('RAW DATA'!D4:D267=A27,'RAW DATA'!I4:I267)),0) -> 0 | F27: =IFERROR(MAX(IF('RAW DATA'!D4:D267=A27,'RAW DATA'!I4:I267)),0) -> 0 | G27: =IFERROR(STDEV(IF('RAW DATA'!D4:D267=A27,'RAW DATA'!I4:I267)),0) -> 0
A28: Electronics | B28: Import | C28: =SUMIF('RAW DATA'!D4:D267,A28,'RAW DATA'!I4:I267) -> 12885 | D28: =IFERROR(AVERAGEIF('RAW DATA'!D4:D267,A28,'RAW DATA'!I4:I267),0) -> 429.5 | E28: =IFERROR(MIN(IF('RAW DATA'!D4:D267=A28,'RAW DATA'!I4:I267)),0) -> 0 | F28: =IFERROR(MAX(IF('RAW DATA'!D4:D267=A28,'RAW DATA'!I4:I267)),0) -> 0 | G28: =IFERROR(STDEV(IF('RAW DATA'!D4:D267=A28,'RAW DATA'!I4:I267)),0) -> 0
A29: Machinery | B29: Import | C29: =SUMIF('RAW DATA'!D4:D267,A29,'RAW DATA'!I4:I267) -> 24929.3 | D29: =IFERROR(AVERAGEIF('RAW DATA'!D4:D267,A29,'RAW DATA'!I4:I267),0) -> 830.97667 | E29: =IFERROR(MIN(IF('RAW DATA'!D4:D267=A29,'RAW DATA'!I4:I267)),0) -> 0 | F29: =IFERROR(MAX(IF('RAW DATA'!D4:D267=A29,'RAW DATA'!I4:I267)),0) -> 0 | G29: =IFERROR(STDEV(IF('RAW DATA'!D4:D267=A29,'RAW DATA'!I4:I267)),0) -> 0
A30: Petroleum Products | B30: Import | C30: =SUMIF('RAW DATA'!D4:D267,A30,'RAW DATA'!I4:I267) -> 64701.3 | D30: =IFERROR(AVERAGEIF('RAW DATA'!D4:D267,A30,'RAW DATA'!I4:I267),0) -> 3594.5167 | E30: =IFERROR(MIN(IF('RAW DATA'!D4:D267=A30,'RAW DATA'!I4:I267)),0) -> 0 | F30: =IFERROR(MAX(IF('RAW DATA'!D4:D267=A30,'RAW DATA'!I4:I267)),0) -> 0 | G30: =IFERROR(STDEV(IF('RAW DATA'!D4:D267=A30,'RAW DATA'!I4:I267)),0) -> 0
A31: Steel | B31: Import | C31: =SUMIF('RAW DATA'!D4:D267,A31,'RAW DATA'!I4:I267) -> 48952.1 | D31: =IFERROR(AVERAGEIF('RAW DATA'!D4:D267,A31,'RAW DATA'!I4:I267),0) -> 2719.5611 | E31: =IFERROR(MIN(IF('RAW DATA'!D4:D267=A31,'RAW DATA'!I4:I267)),0) -> 0 | F31: =IFERROR(MAX(IF('RAW DATA'!D4:D267=A31,'RAW DATA'!I4:I267)),0) -> 0 | G31: =IFERROR(STDEV(IF('RAW DATA'!D4:D267=A31,'RAW DATA'!I4:I267)),0) -> 0
A32: Wheat | B32: Import | C32: =SUMIF('RAW DATA'!D4:D267,A32,'RAW DATA'!I4:I267) -> 52360.5 | D32: =IFERROR(AVERAGEIF('RAW DATA'!D4:D267,A32,'RAW DATA'!I4:I267),0) -> 2908.9167 | E32: =IFERROR(MIN(IF('RAW DATA'!D4:D267=A32,'RAW DATA'!I4:I267)),0) -> 0 | F32: =IFERROR(MAX(IF('RAW DATA'!D4:D267=A32,'RAW DATA'!I4:I267)),0) -> 0 | G32: =IFERROR(STDEV(IF('RAW DATA'!D4:D267=A32,'RAW DATA'!I4:I267)),0) -> 0
A33: Chemicals | B33: Import | C33: =SUMIF('RAW DATA'!D4:D267,A33,'RAW DATA'!I4:I267) -> 19595.3 | D33: =IFERROR(AVERAGEIF('RAW DATA'!D4:D267,A33,'RAW DATA'!I4:I267),0) -> 1088.6278 | E33: =IFERROR(MIN(IF('RAW DATA'!D4:D267=A33,'RAW DATA'!I4:I267)),0) -> 0 | F33: =IFERROR(MAX(IF('RAW DATA'!D4:D267=A33,'RAW DATA'!I4:I267)),0) -> 0 | G33: =IFERROR(STDEV(IF('RAW DATA'!D4:D267=A33,'RAW DATA'!I4:I267)),0) -> 0

Sheet BIVARIATE
A1: STEP 3 · BIVARIATE ANALYSIS — Relationships Between Variables
A2: Cross-tabulation reveals which commodity-partner combinations drive the most trade value, and where Indonesia's exposure is concentrated.
A4: B1 · EXPORT VALUE MATRIX (USD M, All Years) — Commodity × Partner | M4: B3 · CHINA DEPENDENCY ANALYSIS
A5: Commodity | B5: India | C5: China | D5: EU | E5: Japan | F5: South Korea | G5: USA | H5: Pakistan | I5: Philippines | J5: Malaysia | K5: Singapore | L5: ROW TOTAL | M5: Metric | O5: Value
A6: Palm Oil | B6: =SUMIFS('RAW DATA'!H4:H267,'RAW DATA'!D4:D267,A6,'RAW DATA'!F4:F267,B5,'RAW DATA'!C4:C267,"Export") -> 33290 | C6: =SUMIFS('RAW DATA'!H4:H267,'RAW DATA'!D4:D267,A6,'RAW DATA'!F4:F267,C5,'RAW DATA'!C4:C267,"Export") -> 22310 | D6: =SUMIFS('RAW DATA'!H4:H267,'RAW DATA'!D4:D267,A6,'RAW DATA'!F4:F267,D5,'RAW DATA'!C4:C267,"Export") -> 14320 | E6: =SUMIFS('RAW DATA'!H4:H267,'RAW DATA'!D4:D267,A6,'RAW DATA'!F4:F267,E5,'RAW DATA'!C4:C267,"Export") -> 0 | F6: =SUMIFS('RAW DATA'!H4:H267,'RAW DATA'!D4:D267,A6,'RAW DATA'!F4:F267,F5,'RAW DATA'!C4:C267,"Export") -> 0 | G6: =SUMIFS('RAW DATA'!H4:H267,'RAW DATA'!D4:D267,A6,'RAW DATA'!F4:F267,G5,'RAW DATA'!C4:C267,"Export") -> 0 | H6: =SUMIFS('RAW DATA'!H4:H267,'RAW DATA'!D4:D267,A6,'RAW DATA'!F4:F267,H5,'RAW DATA'!C4:C267,"Export") -> 12260 | I6: =SUMIFS('RAW DATA'!H4:H267,'RAW DATA'!D4:D267,A6,'RAW DATA'!F4:F267,I5,'RAW DATA'!C4:C267,"Export") -> 0 | J6: =SUMIFS('RAW DATA'!H4:H267,'RAW DATA'!D4:D267,A6,'RAW DATA'!F4:F267,J5,'RAW DATA'!C4:C267,"Export") -> 6090 | K6: =SUMIFS('RAW DATA'!H4:H267,'RAW DATA'!D4:D267,A6,'RAW DATA'!F4:F267,K5,'RAW DATA'!C4:C267,"Export") -> 0 | L6: =SUM(B6:K6) -> 88270 | M6: China share of total exports | O6: =IFERROR(SUMIFS('RAW DATA'!H4:H267,'RAW DATA'!F4:F267,"China",'RAW DATA'!C4:C267,"Export")/SUMIFS('RAW DATA'!H4:H267,'RAW DATA'!C4:C267,"Export"),0) -> 0.43750231
A7: Coal | B7: =SUMIFS('RAW DATA'!H4:H267,'RAW DATA'!D4:D267,A7,'RAW DATA'!F4:F267,B5,'RAW DATA'!C4:C267,"Export") -> 33660 | C7: =SUMIFS('RAW DATA'!H4:H267,'RAW DATA'!D4:D267,A7,'RAW DATA'!F4:F267,C5,'RAW DATA'!C4:C267,"Export") -> 51930 | D7: =SUMIFS('RAW DATA'!H4:H267,'RAW DATA'!D4:D267,A7,'RAW DATA'!F4:F267,D5,'RAW DATA'!C4:C267,"Export") -> 0 | E7: =SUMIFS('RAW DATA'!H4:H267,'RAW DATA'!D4:D267,A7,'RAW DATA'!F4:F267,E5,'RAW DATA'!C4:C267,"Export") -> 29830 | F7: =SUMIFS('RAW DATA'!H4:H267,'RAW DATA'!D4:D267,A7,'RAW DATA'!F4:F267,F5,'RAW DATA'!C4:C267,"Export") -> 23390 | G7: =SUMIFS('RAW DATA'!H4:H267,'RAW DATA'!D4:D267,A7,'RAW DATA'!F4:F267,G5,'RAW DATA'!C4:C267,"Export") -> 0 | H7: =SUMIFS('RAW DATA'!H4:H267,'RAW DATA'!D4:D267,A7,'RAW DATA'!F4:F267,H5,'RAW DATA'!C4:C267,"Export") -> 0 | I7: =SUMIFS('RAW DATA'!H4:H267,'RAW DATA'!D4:D267,A7,'RAW DATA'!F4:F267,I5,'RAW DATA'!C4:C267,"Export") -> 9800 | J7: =SUMIFS('RAW DATA'!H4:H267,'RAW DATA'!D4:D267,A7,'RAW DATA'!F4:F267,J5,'RAW DATA'!C4:C267,"Export") -> 0 | K7: =SUMIFS('RAW DATA'!H4:H267,'RAW DATA'!D4:D267,A7,'RAW DATA'!F4:F267,K5,'RAW DATA'!C4:C267,"Export") -> 0 | L7: =SUM(B7:K7) -> 148610 | M7: China share of total imports | O7: =IFERROR(SUMIFS('RAW DATA'!H4:H267,'RAW DATA'!F4:F267,"China",'RAW DATA'!C4:C267,"Import")/SUMIFS('RAW DATA'!H4:H267,'RAW DATA'!C4:C267,"Import"),0) -> 0.37301791
A8: Nickel Products | B8: =SUMIFS('RAW DATA'!H4:H267,'RAW DATA'!D4:D267,A8,'RAW DATA'!F4:F267,B5,'RAW DATA'!C4:C267,"Export") -> 0 | C8: =SUMIFS('RAW DATA'!H4:H267,'RAW DATA'!D4:D267,A8,'RAW DATA'!F4:F267,C5,'RAW DATA'!C4:C267,"Export") -> 62580 | D8: =SUMIFS('RAW DATA'!H4:H267,'RAW DATA'!D4:D267,A8,'RAW DATA'!F4:F267,D5,'RAW DATA'!C4:C267,"Export") -> 0 | E8: =SUMIFS('RAW DATA'!H4:H267,'RAW DATA'!D4:D267,A8,'RAW DATA'!F4:F267,E5,'RAW DATA'!C4:C267,"Export") -> 9600 | F8: =SUMIFS('RAW DATA'!H4:H267,'RAW DATA'!D4:D267,A8,'RAW DATA'!F4:F267,F5,'RAW DATA'!C4:C267,"Export") -> 6950 | G8: =SUMIFS('RAW DATA'!H4:H267,'RAW DATA'!D4:D267,A8,'RAW DATA'!F4:F267,G5,'RAW DATA'!C4:C267,"Export") -> 0 | H8: =SUMIFS('RAW DATA'!H4:H267,'RAW DATA'!D4:D267,A8,'RAW DATA'!F4:F267,H5,'RAW DATA'!C4:C267,"Export") -> 0 | I8: =SUMIFS('RAW DATA'!H4:H267,'RAW DATA'!D4:D267,A8,'RAW DATA'!F4:F267,I5,'RAW DATA'!C4:C267,"Export") -> 0 | J8: =SUMIFS('RAW DATA'!H4:H267,'RAW DATA'!D4:D267,A8,'RAW DATA'!F4:F267,J5,'RAW DATA'!C4:C267,"Export") -> 0 | K8: =SUMIFS('RAW DATA'!H4:H267,'RAW DATA'!D4:D267,A8,'RAW DATA'!F4:F267,K5,'RAW DATA'!C4:C267,"Export") -> 0 | L8: =SUM(B8:K8) -> 79130 | M8: China total export value (USD M) | O8: =SUMIFS('RAW DATA'!H4:H267,'RAW DATA'!F4:F267,"China",'RAW DATA'!C4:C267,"Export") -> 166040
A9: Rubber | B9: =SUMIFS('RAW DATA'!H4:H267,'RAW DATA'!D4:D267,A9,'RAW DATA'!F4:F267,B5,'RAW DATA'!C4:C267,"Export") -> 0 | C9: =SUMIFS('RAW DATA'!H4:H267,'RAW DATA'!D4:D267,A9,'RAW DATA'!F4:F267,C5,'RAW DATA'!C4:C267,"Export") -> 10760 | D9: =SUMIFS('RAW DATA'!H4:H267,'RAW DATA'!D4:D267,A9,'RAW DATA'!F4:F267,D5,'RAW DATA'!C4:C267,"Export") -> 0 | E9: =SUMIFS('RAW DATA'!H4:H267,'RAW DATA'!D4:D267,A9,'RAW DATA'!F4:F267,E5,'RAW DATA'!C4:C267,"Export") -> 4200 | F9: =SUMIFS('RAW DATA'!H4:H267,'RAW DATA'!D4:D267,A9,'RAW DATA'!F4:F267,F5,'RAW DATA'!C4:C267,"Export") -> 0 | G9: =SUMIFS('RAW DATA'!H4:H267,'RAW DATA'!D4:D267,A9,'RAW DATA'!F4:F267,G5,'RAW DATA'!C4:C267,"Export") -> 5370 | H9: =SUMIFS('RAW DATA'!H4:H267,'RAW DATA'!D4:D267,A9,'RAW DATA'!F4:F267,H5,'RAW DATA'!C4:C267,"Export") -> 0 | I9: =SUMIFS('RAW DATA'!H4:H267,'RAW DATA'!D4:D267,A9,'RAW DATA'!F4:F267,I5,'RAW DATA'!C4:C267,"Export") -> 0 | J9: =SUMIFS('RAW DATA'!H4:H267,'RAW DATA'!D4:D267,A9,'RAW DATA'!F4:F267,J5,'RAW DATA'!C4:C267,"Export") -> 0 | K9: =SUMIFS('RAW DATA'!H4:H267,'RAW DATA'!D4:D267,A9,'RAW DATA'!F4:F267,K5,'RAW DATA'!C4:C267,"Export") -> 0 | L9: =SUM(B9:K9) -> 20330 | M9: China total import value (USD M) | O9: =SUMIFS('RAW DATA'!H4:H267,'RAW DATA'!F4:F267,"China",'RAW DATA'!C4:C267,"Import") -> 101860
A10: Crude Oil | B10: =SUMIFS('RAW DATA'!H4:H267,'RAW DATA'!D4:D267,A10,'RAW DATA'!F4:F267,B5,'RAW DATA'!C4:C267,"Export") -> 0 | C10: =SUMIFS('RAW DATA'!H4:H267,'RAW DATA'!D4:D267,A10,'RAW DATA'!F4:F267,C5,'RAW DATA'!C4:C267,"Export") -> 18460 | D10: =SUMIFS('RAW DATA'!H4:H267,'RAW DATA'!D4:D267,A10,'RAW DATA'!F4:F267,D5,'RAW DATA'!C4:C267,"Export") -> 0 | E10: =SUMIFS('RAW DATA'!H4:H267,'RAW DATA'!D4:D267,A10,'RAW DATA'!F4:F267,E5,'RAW DATA'!C4:C267,"Export") -> 8740 | F10: =SUMIFS('RAW DATA'!H4:H267,'RAW DATA'!D4:D267,A10,'RAW DATA'!F4:F267,F5,'RAW DATA'!C4:C267,"Export") -> 0 | G10: =SUMIFS('RAW DATA'!H4:H267,'RAW DATA'!D4:D267,A10,'RAW DATA'!F4:F267,G5,'RAW DATA'!C4:C267,"Export") -> 0 | H10: =SUMIFS('RAW DATA'!H4:H267,'RAW DATA'!D4:D267,A10,'RAW DATA'!F4:F267,H5,'RAW DATA'!C4:C267,"Export") -> 0 | I10: =SUMIFS('RAW DATA'!H4:H267,'RAW DATA'!D4:D267,A10,'RAW DATA'!F4:F267,I5,'RAW DATA'!C4:C267,"Export") -> 0 | J10: =SUMIFS('RAW DATA'!H4:H267,'RAW DATA'!D4:D267,A10,'RAW DATA'!F4:F267,J5,'RAW DATA'!C4:C267,"Export") -> 0 | K10: =SUMIFS('RAW DATA'!H4:H267,'RAW DATA'!D4:D267,A10,'RAW DATA'!F4:F267,K5,'RAW DATA'!C4:C267,"Export") -> 10520 | L10: =SUM(B10:K10) -> 37720 | M10: China trade balance (USD M) | O10: =SUMIFS('RAW DATA'!H4:H267,'RAW DATA'!F4:F267,"China",'RAW DATA'!C4:C267,"Export")-SUMIFS('RAW DATA'!H4:H267,'RAW DATA'!F4:F267,"China",'RAW DATA'!C4:C267,"Import") -> 64180
A11: Coffee | B11: =SUMIFS('RAW DATA'!H4:H267,'RAW DATA'!D4:D267,A11,'RAW DATA'!F4:F267,B5,'RAW DATA'!C4:C267,"Export") -> 0 | C11: =SUMIFS('RAW DATA'!H4:H267,'RAW DATA'!D4:D267,A11,'RAW DATA'!F4:F267,C5,'RAW DATA'!C4:C267,"Export") -> 0 | D11: =SUMIFS('RAW DATA'!H4:H267,'RAW DATA'!D4:D267,A11,'RAW DATA'!F4:F267,D5,'RAW DATA'!C4:C267,"Export") -> 2036 | E11: =SUMIFS('RAW DATA'!H4:H267,'RAW DATA'!D4:D267,A11,'RAW DATA'!F4:F267,E5,'RAW DATA'!C4:C267,"Export") -> 884 | F11: =SUMIFS('RAW DATA'!H4:H267,'RAW DATA'!D4:D267,A11,'RAW DATA'!F4:F267,F5,'RAW DATA'!C4:C267,"Export") -> 0 | G11: =SUMIFS('RAW DATA'!H4:H267,'RAW DATA'!D4:D267,A11,'RAW DATA'!F4:F267,G5,'RAW DATA'!C4:C267,"Export") -> 2538 | H11: =SUMIFS('RAW DATA'!H4:H267,'RAW DATA'!D4:D267,A11,'RAW DATA'!F4:F267,H5,'RAW DATA'!C4:C267,"Export") -> 0 | I11: =SUMIFS('RAW DATA'!H4:H267,'RAW DATA'!D4:D267,A11,'RAW DATA'!F4:F267,I5,'RAW DATA'!C4:C267,"Export") -> 0 | J11: =SUMIFS('RAW DATA'!H4:H267,'RAW DATA'!D4:D267,A11,'RAW DATA'!F4:F267,J5,'RAW DATA'!C4:C267,"Export") -> 0 | K11: =SUMIFS('RAW DATA'!H4:H267,'RAW DATA'!D4:D267,A11,'RAW DATA'!F4:F267,K5,'RAW DATA'!C4:C267,"Export") -> 0 | L11: =SUM(B11:K11) -> 5458 | M11: Top commodity to China (by value) | P11: Coal & Nickel Products
A12: COL TOTAL | B12: =SUM(B6:B11) -> 66950 | C12: =SUM(C6:C11) -> 166040 | D12: =SUM(D6:D11) -> 16356 | E12: =SUM(E6:E11) -> 53254 | F12: =SUM(F6:F11) -> 30340 | G12: =SUM(G6:G11) -> 7908 | H12: =SUM(H6:H11) -> 12260 | I12: =SUM(I6:I11) -> 9800 | ... L12: =SUM(L6:L11) -> 379518 | M12: Top commodity from China (by value) | O12: Machinery & Electronics
A15: B2 · IMPORT VALUE MATRIX (USD M, All Years) — Commodity × Partner
A16: Commodity | B16: China | C16: Japan | D16: Singapore | E16: Germany | F16: USA | G16: South Korea | H16: Malaysia | I16: Saudi Arabia | J16: Australia | K16: Canada | L16: ROW TOTAL
A17: Electronics | B17: =SUMIFS('RAW DATA'!H4:H267,'RAW DATA'!D4:D267,A17,'RAW DATA'!F4:F267,B16,'RAW DATA'!C4:C267,"Import") -> 32140 | C17: =SUMIFS('RAW DATA'!H4:H267,'RAW DATA'!D4:D267,A17,'RAW DATA'!F4:F267,C16,'RAW DATA'!C4:C267,"Import") -> 9340 | D17: =SUMIFS('RAW DATA'!H4:H267,'RAW DATA'!D4:D267,A17,'RAW DATA'!F4:F267,D16,'RAW DATA'!C4:C267,"Import") -> 12940 | E17: =SUMIFS('RAW DATA'!H4:H267,'RAW DATA'!D4:D267,A17,'RAW DATA'!F4:F267,E16,'RAW DATA'!C4:C267,"Import") -> 0 | F17: =SUMIFS('RAW DATA'!H4:H267,'RAW DATA'!D4:D267,A17,'RAW DATA'!F4:F267,F16,'RAW DATA'!C4:C267,"Import") -> 6100 | G17: =SUMIFS('RAW DATA'!H4:H267,'RAW DATA'!D4:D267,A17,'RAW DATA'!F4:F267,G16,'RAW DATA'!C4:C267,"Import") -> 10740 | H17: =SUMIFS('RAW DATA'!H4:H267,'RAW DATA'!D4:D267,A17,'RAW DATA'!F4:F267,H16,'RAW DATA'!C4:C267,"Import") -> 0 | I17: =SUMIFS('RAW DATA'!H4:H267,'RAW DATA'!D4:D267,A17,'RAW DATA'!F4:F267,I16,'RAW DATA'!C4:C267,"Import") -> 0 | J17: =SUMIFS('RAW DATA'!H4:H267,'RAW DATA'!D4:D267,A17,'RAW DATA'!F4:F267,J16,'RAW DATA'!C4:C267,"Import") -> 0 | K17: =SUMIFS('RAW DATA'!H4:H267,'RAW DATA'!D4:D267,A17,'RAW DATA'!F4:F267,K16,'RAW DATA'!C4:C267,"Import") -> 0 | L17: =SUM(B17:K17) -> 71260
A18: Machinery | B18: =SUMIFS('RAW DATA'!H4:H267,'RAW DATA'!D4:D267,A18,'RAW DATA'!F4:F267,B16,'RAW DATA'!C4:C267,"Import") -> 36740 | C18: =SUMIFS('RAW DATA'!H4:H267,'RAW DATA'!D4:D267,A18,'RAW DATA'!F4:F267,C16,'RAW DATA'!C4:C267,"Import") -> 18540 | D18: =SUMIFS('RAW DATA'!H4:H267,'RAW DATA'!D4:D267,A18,'RAW DATA'!F4:F267,D16,'RAW DATA'!C4:C267,"Import") -> 7540 | E18: =SUMIFS('RAW DATA'!H4:H267,'RAW DATA'!D4:D267,A18,'RAW DATA'!F4:F267,E16,'RAW DATA'!C4:C267,"Import") -> 12040 | F18: =SUMIFS('RAW DATA'!H4:H267,'RAW DATA'!D4:D267,A18,'RAW DATA'!F4:F267,F16,'RAW DATA'!C4:C267,"Import") -> 10040 | G18: =SUMIFS('RAW DATA'!H4:H267,'RAW DATA'!D4:D267,A18,'RAW DATA'!F4:F267,G16,'RAW DATA'!C4:C267,"Import") -> 0 | H18: =SUMIFS('RAW DATA'!H4:H267,'RAW DATA'!D4:D267,A18,'RAW DATA'!F4:F267,H16,'RAW DATA'!C4:C267,"Import") -> 0 | I18: =SUMIFS('RAW DATA'!H4:H267,'RAW DATA'!D4:D267,A18,'RAW DATA'!F4:F267,I16,'RAW DATA'!C4:C267,"Import") -> 0 | J18: =SUMIFS('RAW DATA'!H4:H267,'RAW DATA'!D4:D267,A18,'RAW DATA'!F4:F267,J16,'RAW DATA'!C4:C267,"Import") -> 0 | K18: =SUMIFS('RAW DATA'!H4:H267,'RAW DATA'!D4:D267,A18,'RAW DATA'!F4:F267,K16,'RAW DATA'!C4:C267,"Import") -> 0 | L18: =SUM(B18:K18) -> 84900
A19: Petroleum Products | B19: =SUMIFS('RAW DATA'!H4:H267,'RAW DATA'!D4:D267,A19,'RAW DATA'!F4:F267,B16,'RAW DATA'!C4:C267,"Import") -> 0 | C19: =SUMIFS('RAW DATA'!H4:H267,'RAW DATA'!D4:D267,A19,'RAW DATA'!F4:F267,C16,'RAW DATA'!C4:C267,"Import") -> 0 | D19: =SUMIFS('RAW DATA'!H4:H267,'RAW DATA'!D4:D267,A19,'RAW DATA'!F4:F267,D16,'RAW DATA'!C4:C267,"Import") -> 22640 | E19: =SUMIFS('RAW DATA'!H4:H267,'RAW DATA'!D4:D267,A19,'RAW DATA'!F4:F267,E16,'RAW DATA'!C4:C267,"Import") -> 0 | F19: =SUMIFS('RAW DATA'!H4:H267,'RAW DATA'!D4:D267,A19,'RAW DATA'!F4:F267,F16,'RAW DATA'!C4:C267,"Import") -> 0 | G19: =SUMIFS('RAW DATA'!H4:H267,'RAW DATA'!D4:D267,A19,'RAW DATA'!F4:F267,G16,'RAW DATA'!C4:C267,"Import") -> 0 | H19: =SUMIFS('RAW DATA'!H4:H267,'RAW DATA'!D4:D267,A19,'RAW DATA'!F4:F267,H16,'RAW DATA'!C4:C267,"Import") -> 11640 | I19: =SUMIFS('RAW DATA'!H4:H267,'RAW DATA'!D4:D267,A19,'RAW DATA'!F4:F267,I16,'RAW DATA'!C4:C267,"Import") -> 8940 | J19: =SUMIFS('RAW DATA'!H4:H267,'RAW DATA'!D4:D267,A19,'RAW DATA'!F4:F267,J16,'RAW DATA'!C4:C267,"Import") -> 0 | K19: =SUMIFS('RAW DATA'!H4:H267,'RAW DATA'!D4:D267,A19,'RAW DATA'!F4:F267,K16,'RAW DATA'!C4:C267,"Import") -> 0 | L19: =SUM(B19:K19) -> 43220
A20: Steel | B20: =SUMIFS('RAW DATA'!H4:H267,'RAW DATA'!D4:D267,A20,'RAW DATA'!F4:F267,B16,'RAW DATA'!C4:C267,"Import") -> 20640 | C20: =SUMIFS('RAW DATA'!H4:H267,'RAW DATA'!D4:D267,A20,'RAW DATA'!F4:F267,C16,'RAW DATA'!C4:C267,"Import") -> 7880 | D20: =SUMIFS('RAW DATA'!H4:H267,'RAW DATA'!D4:D267,A20,'RAW DATA'!F4:F267,D16,'RAW DATA'!C4:C267,"Import") -> 0 | E20: =SUMIFS('RAW DATA'!H4:H267,'RAW DATA'!D4:D267,A20,'RAW DATA'!F4:F267,E16,'RAW DATA'!C4:C267,"Import") -> 0 | F20: =SUMIFS('RAW DATA'!H4:H267,'RAW DATA'!D4:D267,A20,'RAW DATA'!F4:F267,F16,'RAW DATA'!C4:C267,"Import") -> 0 | G20: =SUMIFS('RAW DATA'!H4:H267,'RAW DATA'!D4:D267,A20,'RAW DATA'!F4:F267,G16,'RAW DATA'!C4:C267,"Import") -> 6520 | H20: =SUMIFS('RAW DATA'!H4:H267,'RAW DATA'!D4:D267,A20,'RAW DATA'!F4:F267,H16,'RAW DATA'!C4:C267,"Import") -> 0 | I20: =SUMIFS('RAW DATA'!H4:H267,'RAW DATA'!D4:D267,A20,'RAW DATA'!F4:F267,I16,'RAW DATA'!C4:C267,"Import") -> 0 | J20: =SUMIFS('RAW DATA'!H4:H267,'RAW DATA'!D4:D267,A20,'RAW DATA'!F4:F267,J16,'RAW DATA'!C4:C267,"Import") -> 0 | K20: =SUMIFS('RAW DATA'!H4:H267,'RAW DATA'!D4:D267,A20,'RAW DATA'!F4:F267,K16,'RAW DATA'!C4:C267,"Import") -> 0 | L20: =SUM(B20:K20) -> 35040
A21: Wheat | B21: =SUMIFS('RAW DATA'!H4:H267,'RAW DATA'!D4:D267,A21,'RAW DATA'!F4:F267,B16,'RAW DATA'!C4:C267,"Import") -> 0 | C21: =SUMIFS('RAW DATA'!H4:H267,'RAW DATA'!D4:D267,A21,'RAW DATA'!F4:F267,C16,'RAW DATA'!C4:C267,"Import") -> 0 | D21: =SUMIFS('RAW DATA'!H4:H267,'RAW DATA'!D4:D267,A21,'RAW DATA'!F4:F267,D16,'RAW DATA'!C4:C267,"Import") -> 0 | E21: =SUMIFS('RAW DATA'!H4:H267,'RAW DATA'!D4:D267,A21,'RAW DATA'!F4:F267,E16,'RAW DATA'!C4:C267,"Import") -> 0 | F21: =SUMIFS('RAW DATA'!H4:H267,'RAW DATA'!D4:D267,A21,'RAW DATA'!F4:F267,F16,'RAW DATA'!C4:C267,"Import") -> 0 | G21: =SUMIFS('RAW DATA'!H4:H267,'RAW DATA'!D4:D267,A21,'RAW DATA'!F4:F267,G16,'RAW DATA'!C4:C267,"Import") -> 0 | H21: =SUMIFS('RAW DATA'!H4:H267,'RAW DATA'!D4:D267,A21,'RAW DATA'!F4:F267,H16,'RAW DATA'!C4:C267,"Import") -> 0 | I21: =SUMIFS('RAW DATA'!H4:H267,'RAW DATA'!D4:D267,A21,'RAW DATA'!F4:F267,I16,'RAW DATA'!C4:C267,"Import") -> 0 | J21: =SUMIFS('RAW DATA'!H4:H267,'RAW DATA'!D4:D267,A21,'RAW DATA'!F4:F267,J16,'RAW DATA'!C4:C267,"Import") -> 7150 | K21: =SUMIFS('RAW DATA'!H4:H267,'RAW DATA'!D4:D267,A21,'RAW DATA'!F4:F267,K16,'RAW DATA'!C4:C267,"Import") -> 4810 | L21: =SUM(B21:K21) -> 11960
A22: Chemicals | B22: =SUMIFS('RAW DATA'!H4:H267,'RAW DATA'!D4:D267,A22,'RAW DATA'!F4:F267,B16,'RAW DATA'!C4:C267,"Import") -> 12340 | C22: =SUMIFS('RAW DATA'!H4:H267,'RAW DATA'!D4:D267,A22,'RAW DATA'!F4:F267,C16,'RAW DATA'!C4:C267,"Import") -> 0 | D22: =SUMIFS('RAW DATA'!H4:H267,'RAW DATA'!D4:D267,A22,'RAW DATA'!F4:F267,D16,'RAW DATA'!C4:C267,"Import") -> 7400 | E22: =SUMIFS('RAW DATA'!H4:H267,'RAW DATA'!D4:D267,A22,'RAW DATA'!F4:F267,E16,'RAW DATA'!C4:C267,"Import") -> 4740 | F22: =SUMIFS('RAW DATA'!H4:H267,'RAW DATA'!D4:D267,A22,'RAW DATA'!F4:F267,F16,'RAW DATA'!C4:C267,"Import") -> 0 | G22: =SUMIFS('RAW DATA'!H4:H267,'RAW DATA'!D4:D267,A22,'RAW DATA'!F4:F267,G16,'RAW DATA'!C4:C267,"Import") -> 0 | H22: =SUMIFS('RAW DATA'!H4:H267,'RAW DATA'!D4:D267,A22,'RAW DATA'!F4:F267,H16,'RAW DATA'!C4:C267,"Import") -> 0 | I22: =SUMIFS('RAW DATA'!H4:H267,'RAW DATA'!D4:D267,A22,'RAW DATA'!F4:F267,I16,'RAW DATA'!C4:C267,"Import") -> 0 | J22: =SUMIFS('RAW DATA'!H4:H267,'RAW DATA'!D4:D267,A22,'RAW DATA'!F4:F267,J16,'RAW DATA'!C4:C267,"Import") -> 0 | K22: =SUMIFS('RAW DATA'!H4:H267,'RAW DATA'!D4:D267,A22,'RAW DATA'!F4:F267,K16,'RAW DATA'!C4:C267,"Import") -> 0 | L22: =SUM(B22:K22) -> 24480
A23: COL TOTAL | B23: =SUM(B17:B22) -> 101860 | C23: =SUM(C17:C22) -> 35760 | D23: =SUM(D17:D22) -> 50520 | E23: =SUM(E17:E22) -> 16780 | F23: =SUM(F17:F22) -> 16140 | G23: =SUM(G17:G22) -> 17260 | H23: =SUM(H17:H22) -> 11640 | I23: =SUM(I17:I22) -> 8940 | ... L23: =SUM(L17:L22) -> 270860

Sheet TIME SERIES
A1: STEP 4 · TIME SERIES ANALYSIS — Trends, Growth & CAGR 2019–2024
A2: Time series analysis reveals growth trajectories, cyclicality, and structural shifts in trade flows over time.
A4: T1 · ANNUAL TOTAL TRADE VALUE (USD M) — Exports vs Imports
A5: Metric | B5: 2019 | C5: 2020 | D5: 2021 | E5: 2022 | F5: 2023 | G5: 2024 | H5: CAGR | I5: 2020 YoY | J5: 2021 YoY | K5: 2022 YoY | L5: 2023 YoY | M5: 2024 YoY | N5: Trend Note
A6: Total Exports | B6: =SUMIFS('RAW DATA'!H4:H267,'RAW DATA'!C4:C267,"Export",'RAW DATA'!B4:B267,2019) -> 47442 | C6: =SUMIFS('RAW DATA'!H4:H267,'RAW DATA'!C4:C267,"Export",'RAW DATA'!B4:B267,2020) -> 37208 | D6: =SUMIFS('RAW DATA'!H4:H267,'RAW DATA'!C4:C267,"Export",'RAW DATA'!B4:B267,2021) -> 57636 | E6: =SUMIFS('RAW DATA'!H4:H267,'RAW DATA'!C4:C267,"Export",'RAW DATA'!B4:B267,2022) -> 86916 | F6: =SUMIFS('RAW DATA'!H4:H267,'RAW DATA'!C4:C267,"Export",'RAW DATA'!B4:B267,2023) -> 75926 | G6: =SUMIFS('RAW DATA'!H4:H267,'RAW DATA'!C4:C267,"Export",'RAW DATA'!B4:B267,2024) -> 74390 | H6: =IFERROR((G6/B6)^(1/5)-1,0) -> 0.094133496 | I6: =IFERROR(C6/B6-1,0) -> -0.21571603 | J6: =IFERROR(D6/C6-1,0) -> 0.54902172 | K6: =IFERROR(E6/D6-1,0) -> 0.50801582 | L6: =IFERROR(F6/E6-1,0) -> -0.12644392 | M6: =IFERROR(G6/F6-1,0) -> -0.020230224
A7: Total Imports | B7: =SUMIFS('RAW DATA'!H4:H267,'RAW DATA'!C4:C267,"Import",'RAW DATA'!B4:B267,2019) -> 41620 | C7: =SUMIFS('RAW DATA'!H4:H267,'RAW DATA'!C4:C267,"Import",'RAW DATA'!B4:B267,2020) -> 32570 | D7: =SUMIFS('RAW DATA'!H4:H267,'RAW DATA'!C4:C267,"Import",'RAW DATA'!B4:B267,2021) -> 43060 | E7: =SUMIFS('RAW DATA'!H4:H267,'RAW DATA'!C4:C267,"Import",'RAW DATA'!B4:B267,2022) -> 53770 | F7: =SUMIFS('RAW DATA'!H4:H267,'RAW DATA'!C4:C267,"Import",'RAW DATA'!B4:B267,2023) -> 48540 | G7: =SUMIFS('RAW DATA'!H4:H267,'RAW DATA'!C4:C267,"Import",'RAW DATA'!B4:B267,2024) -> 53510 | H7: =IFERROR((G7/B7)^(1/5)-1,0) -> 0.051541882 | I7: =IFERROR(C7/B7-1,0) -> -0.21744354 | J7: =IFERROR(D7/C7-1,0) -> 0.32207553 | K7: =IFERROR(E7/D7-1,0) -> 0.24872271 | L7: =IFERROR(F7/E7-1,0) -> -0.097266134 | M7: =IFERROR(G7/F7-1,0) -> 0.10238978
A8: Trade Balance | B8: =B6-B7 -> 5822 | C8: =C6-C7 -> 4638 | D8: =D6-D7 -> 14576 | E8: =E6-E7 -> 33146 | F8: =F6-F7 -> 27386 | G8: =G6-G7 -> 20880
A11: T2 · EXPORT COMMODITY TRENDS (USD M) — Year by Year
A12: Commodity | B12: 2019 | C12: 2020 | D12: 2021 | E12: 2022 | F12: 2023 | G12: 2024 | H12: CAGR | I12: 2020 | J12: 2021 | K12: 2022 | L12: 2023 | M12: 2024 | N12: Key Driver
A13: Palm Oil | B13: =SUMIFS('RAW DATA'!H4:H267,'RAW DATA'!D4:D267,A13,'RAW DATA'!B4:B267,2019) -> 12940 | C13: =SUMIFS('RAW DATA'!H4:H267,'RAW DATA'!D4:D267,A13,'RAW DATA'!B4:B267,2020) -> 11360 | D13: =SUMIFS('RAW DATA'!H4:H267,'RAW DATA'!D4:D267,A13,'RAW DATA'!B4:B267,2021) -> 14080 | E13: =SUMIFS('RAW DATA'!H4:H267,'RAW DATA'!D4:D267,A13,'RAW DATA'!B4:B267,2022) -> 17990 | F13: =SUMIFS('RAW DATA'!H4:H267,'RAW DATA'!D4:D267,A13,'RAW DATA'!B4:B267,2023) -> 15520 | G13: =SUMIFS('RAW DATA'!H4:H267,'RAW DATA'!D4:D267,A13,'RAW DATA'!B4:B267,2024) -> 16380 | H13: =IFERROR((G13/B13)^(1/5)-1,0) -> 0.048276679 | I13: =IFERROR(C13/B13-1,0) -> -0.12210201 | J13: =IFERROR(D13/C13-1,0) -> 0.23943662 | K13: =IFERROR(E13/D13-1,0) -> 0.27769886 | L13: =IFERROR(F13/E13-1,0) -> -0.1372985 | M13: =IFERROR(G13/F13-1,0) -> 0.055412371 | N13: CPO price volatility
A14: Coal | B14: =SUMIFS('RAW DATA'!H4:H267,'RAW DATA'!D4:D267,A14,'RAW DATA'!B4:B267,2019) -> 18770 | C14: =SUMIFS('RAW DATA'!H4:H267,'RAW DATA'!D4:D267,A14,'RAW DATA'!B4:B267,2020) -> 12570 | D14: =SUMIFS('RAW DATA'!H4:H267,'RAW DATA'!D4:D267,A14,'RAW DATA'!B4:B267,2021) -> 24430 | E14: =SUMIFS('RAW DATA'!H4:H267,'RAW DATA'!D4:D267,A14,'RAW DATA'!B4:B267,2022) -> 40170 | F14: =SUMIFS('RAW DATA'!H4:H267,'RAW DATA'!D4:D267,A14,'RAW DATA'!B4:B267,2023) -> 28120 | G14: =SUMIFS('RAW DATA'!H4:H267,'RAW DATA'!D4:D267,A14,'RAW DATA'!B4:B267,2024) -> 24550 | H14: =IFERROR((G14/B14)^(1/5)-1,0) -> 0.055157875 | I14: =IFERROR(C14/B14-1,0) -> -0.33031433 | J14: =IFERROR(D14/C14-1,0) -> 0.94351631 | K14: =IFERROR(E14/D14-1,0) -> 0.64428981 | L14: =IFERROR(F14/E14-1,0) -> -0.29997511 | M14: =IFERROR(G14/F14-1,0) -> -0.1269559 | N14: 2022 energy crisis spike
A15: Nickel Products | B15: =SUMIFS('RAW DATA'!H4:H267,'RAW DATA'!D4:D267,A15,'RAW DATA'!B4:B267,2019) -> 4880 | C15: =SUMIFS('RAW DATA'!H4:H267,'RAW DATA'!D4:D267,A15,'RAW DATA'!B4:B267,2020) -> 5790 | D15: =SUMIFS('RAW DATA'!H4:H267,'RAW DATA'!D4:D267,A15,'RAW DATA'!B4:B267,2021) -> 9220 | E15: =SUMIFS('RAW DATA'!H4:H267,'RAW DATA'!D4:D267,A15,'RAW DATA'!B4:B267,2022) -> 15270 | F15: =SUMIFS('RAW DATA'!H4:H267,'RAW DATA'!D4:D267,A15,'RAW DATA'!B4:B267,2023) -> 20980 | G15: =SUMIFS('RAW DATA'!H4:H267,'RAW DATA'!D4:D267,A15,'RAW DATA'!B4:B267,2024) -> 22990 | H15: =IFERROR((G15/B15)^(1/5)-1,0) -> 0.3634017 | I15: =IFERROR(C15/B15-1,0) -> 0.18647541 | J15: =IFERROR(D15/C15-1,0) -> 0.59240069 | K15: =IFERROR(E15/D15-1,0) -> 0.65618221 | L15: =IFERROR(F15/E15-1,0) -> 0.37393582 | M15: =IFERROR(G15/F15-1,0) -> 0.095805529 | N15: EV battery demand surge
A16: Rubber | B16: =SUMIFS('RAW DATA'!H4:H267,'RAW DATA'!D4:D267,A16,'RAW DATA'!B4:B267,2019) -> 3470 | C16: =SUMIFS('RAW DATA'!H4:H267,'RAW DATA'!D4:D267,A16,'RAW DATA'!B4:B267,2020) -> 2690 | D16: =SUMIFS('RAW DATA'!H4:H267,'RAW DATA'!D4:D267,A16,'RAW DATA'!B4:B267,2021) -> 3260 | E16: =SUMIFS('RAW DATA'!H4:H267,'RAW DATA'!D4:D267,A16,'RAW DATA'!B4:B267,2022) -> 4010 | F16: =SUMIFS('RAW DATA'!H4:H267,'RAW DATA'!D4:D267,A16,'RAW DATA'!B4:B267,2023) -> 3250 | G16: =SUMIFS('RAW DATA'!H4:H267,'RAW DATA'!D4:D267,A16,'RAW DATA'!B4:B267,2024) -> 3650 | H16: =IFERROR((G16/B16)^(1/5)-1,0) -> 0.010165839 | I16: =IFERROR(C16/B16-1,0) -> -0.22478386 | J16: =IFERROR(D16/C16-1,0) -> 0.21189591 | K16: =IFERROR(E16/D16-1,0) -> 0.23006135 | L16: =IFERROR(F16/E16-1,0) -> -0.18952618 | M16: =IFERROR(G16/F16-1,0) -> 0.12307692 | N16: Auto sector correlation
A17: Crude Oil | B17: =SUMIFS('RAW DATA'!H4:H267,'RAW DATA'!D4:D267,A17,'RAW DATA'!B4:B267,2019) -> 6620 | C17: =SUMIFS('RAW DATA'!H4:H267,'RAW DATA'!D4:D267,A17,'RAW DATA'!B4:B267,2020) -> 4100 | D17: =SUMIFS('RAW DATA'!H4:H267,'RAW DATA'!D4:D267,A17,'RAW DATA'!B4:B267,2021) -> 5800 | E17: =SUMIFS('RAW DATA'!H4:H267,'RAW DATA'!D4:D267,A17,'RAW DATA'!B4:B267,2022) -> 8340 | F17: =SUMIFS('RAW DATA'!H4:H267,'RAW DATA'!D4:D267,A17,'RAW DATA'!B4:B267,2023) -> 7020 | G17: =SUMIFS('RAW DATA'!H4:H267,'RAW DATA'!D4:D267,A17,'RAW DATA'!B4:B267,2024) -> 5840 | H17: =IFERROR((G17/B17)^(1/5)-1,0) -> -0.0247612 | I17: =IFERROR(C17/B17-1,0) -> -0.38066465 | J17: =IFERROR(D17/C17-1,0) -> 0.41463415 | K17: =IFERROR(E17/D17-1,0) -> 0.43793103 | L17: =IFERROR(F17/E17-1,0) -> -0.15827338 | M17: =IFERROR(G17/F17-1,0) -> -0.16809117 | N17: Oil price & depletion
A18: Coffee | B18: =SUMIFS('RAW DATA'!H4:H267,'RAW DATA'!D4:D267,A18,'RAW DATA'!B4:B267,2019) -> 762 | C18: =SUMIFS('RAW DATA'!H4:H267,'RAW DATA'!D4:D267,A18,'RAW DATA'!B4:B267,2020) -> 698 | D18: =SUMIFS('RAW DATA'!H4:H267,'RAW DATA'!D4:D267,A18,'RAW DATA'!B4:B267,2021) -> 846 | E18: =SUMIFS('RAW DATA'!H4:H267,'RAW DATA'!D4:D267,A18,'RAW DATA'!B4:B267,2022) -> 1136 | F18: =SUMIFS('RAW DATA'!H4:H267,'RAW DATA'!D4:D267,A18,'RAW DATA'!B4:B267,2023) -> 1036 | G18: =SUMIFS('RAW DATA'!H4:H267,'RAW DATA'!D4:D267,A18,'RAW DATA'!B4:B267,2024) -> 980 | H18: =IFERROR((G18/B18)^(1/5)-1,0) -> 0.051608822 | I18: =IFERROR(C18/B18-1,0) -> -0.083989501 | J18: =IFERROR(D18/C18-1,0) -> 0.21203438 | K18: =IFERROR(E18/D18-1,0) -> 0.3427896 | L18: =IFERROR(F18/E18-1,0) -> -0.088028169 | M18: =IFERROR(G18/F18-1,0) -> -0.054054054 | N18: Arabica price premium

Sheet TRADE BALANCE
A1: STEP 5 · TRADE BALANCE ANALYSIS — Surplus, Deficit & Partner Exposure
A2: Trade balance = Total Exports − Total Imports. Positive = surplus (Indonesia earns more than it spends).
A4: TB1 · TRADE BALANCE BY PARTNER (USD M, All Years Combined)
A5: Trading Partner | C5: Total Exports | D5: Total Imports | E5: Trade Balance | F5: Balance % | G5: Position | H5: 2024 Exports | I5: 2024 Imports | J5: 2024 Balance | K5: Trend 2019→2024 | L5: Key Commodity
A6: China | C6: =SUMIFS('RAW DATA'!H4:H267,'RAW DATA'!F4:F267,A6,'RAW DATA'!C4:C267,"Export") -> 166040 | D6: =SUMIFS('RAW DATA'!H4:H267,'RAW DATA'!F4:F267,A6,'RAW DATA'!C4:C267,"Import") -> 101860 | E6: =C6-D6 -> 64180 | F6: =IFERROR(E6/(C6+D6),0) -> 0.239567 | G6: =IF(E6>0,"✅ Surplus","🔴 Deficit") -> ✅ Surplus | H6: =SUMIFS('RAW DATA'!H4:H267,'RAW DATA'!F4:F267,A6,'RAW DATA'!C4:C267,"Export",'RAW DATA'!B4:B267,2024) -> 35690 | I6: =SUMIFS('RAW DATA'!H4:H267,'RAW DATA'!F4:F267,A6,'RAW DATA'!C4:C267,"Import",'RAW DATA'!B4:B267,2024) -> 20260 | J6: =H6-I6 -> 15430 | K6: =IFERROR(SUMIFS('RAW DATA'!H4:H267,'RAW DATA'!F4:F267,A6,'RAW DATA'!C4:C267,"Export",'RAW DATA'!B4:B267,2024)/SUMIFS('RAW DATA'!H4:H267,'RAW DATA'!F4:F267,A6,'RAW DATA'!C4:C267,"Export",'RAW DATA'!B4:B267,2019)-1,0) -> 0.90855615 | L6: Coal, Nickel
A7: India | C7: =SUMIFS('RAW DATA'!H4:H267,'RAW DATA'!F4:F267,A7,'RAW DATA'!C4:C267,"Export") -> 66950 | D7: =SUMIFS('RAW DATA'!H4:H267,'RAW DATA'!F4:F267,A7,'RAW DATA'!C4:C267,"Import") -> 0 | E7: =C7-D7 -> 66950 | F7: =IFERROR(E7/(C7+D7),0) -> 1 | G7: =IF(E7>0,"✅ Surplus","🔴 Deficit") -> ✅ Surplus | H7: =SUMIFS('RAW DATA'!H4:H267,'RAW DATA'!F4:F267,A7,'RAW DATA'!C4:C267,"Export",'RAW DATA'!B4:B267,2024) -> 11810 | I7: =SUMIFS('RAW DATA'!H4:H267,'RAW DATA'!F4:F267,A7,'RAW DATA'!C4:C267,"Import",'RAW DATA'!B4:B267,2024) -> 0 | J7: =H7-I7 -> 11810 | K7: =IFERROR(SUMIFS('RAW DATA'!H4:H267,'RAW DATA'!F4:F267,A7,'RAW DATA'!C4:C267,"Export",'RAW DATA'!B4:B267,2024)/SUMIFS('RAW DATA'!H4:H267,'RAW DATA'!F4:F267,A7,'RAW DATA'!C4:C267,"Export",'RAW DATA'!B4:B267,2019)-1,0) -> 0.30209482 | L7: Palm Oil
A8: Japan | C8: =SUMIFS('RAW DATA'!H4:H267,'RAW DATA'!F4:F267,A8,'RAW DATA'!C4:C267,"Export") -> 53254 | D8: =SUMIFS('RAW DATA'!H4:H267,'RAW DATA'!F4:F267,A8,'RAW DATA'!C4:C267,"Import") -> 35760 | E8: =C8-D8 -> 17494 | F8: =IFERROR(E8/(C8+D8),0) -> 0.19653088 | G8: =IF(E8>0,"✅ Surplus","🔴 Deficit") -> ✅ Surplus | H8: =SUMIFS('RAW DATA'!H4:H267,'RAW DATA'!F4:F267,A8,'RAW DATA'!C4:C267,"Export",'RAW DATA'!B4:B267,2024) -> 9948 | I8: =SUMIFS('RAW DATA'!H4:H267,'RAW DATA'!F4:F267,A8,'RAW DATA'!C4:C267,"Import",'RAW DATA'!B4:B267,2024) -> 7020 | J8: =H8-I8 -> 2928 | K8: =IFERROR(SUMIFS('RAW DATA'!H4:H267,'RAW DATA'!F4:F267,A8,'RAW DATA'!C4:C267,"Export",'RAW DATA'!B4:B267,2024)/SUMIFS('RAW DATA'!H4:H267,'RAW DATA'!F4:F267,A8,'RAW DATA'!C4:C267,"Export",'RAW DATA'!B4:B267,2019)-1,0) -> 0.45993543 | L8: Coal, Crude Oil
